Workbook

Sheet 7р хавсралт_322.58тэрбум
A1: НӨХӨХ ОЛГОВРЫН МЭДЭЭ
K2: 26.07.27
A3: № | B3: Саналын хуудасны дугаар | C3: НЗД-ын захирамжийн огноо дугаар | D3: Нэгж талбарын тоо | E3: Талбайн хэмжээ /м2/ | F3: Хөрөнгийн эх үүсвэр 2026 оны "Газар чөлөөлөх нөхөх олговор" 322.582 тэрбум | G3: ОУ-ын СБХБ-ны Улаанбаатар хотын тогтвортой авто зам тээвэр төсөл 19,001,526,923.5 төгрөг | H3: Байршил | I3: Ажлын төрөл | J3: Хугацаа | K3: Төсөв
A4: Гарсан захирамж
A5: 1 | B5: Ү-01 | C5: 2026.01.05 А/04 | F5: 2000000000 | H5: Эрх шилжүүлэх тухай, хөрөнгийн үнэлгээ | I5: Хөрөнгийн үнэлгээ | J5: 2026 | K5: Нийслэл
A6: 2 | B6: C | C6: 2026.01.08 А/16 | D6: 1 | E6: 546 | F6: 2450517000 | H6: Сүхбаатар дүүрэг, Чингэлтэй дүүрэг Сэлбэ дэд төв | I6: Дэд төв | J6: 2026 | K6: Нийслэл
A7: 3 | B7: II-97 | C7: 2026.01.09 А/34 | D7: 1 | E7: 55.3 | F7: 35580000 | H7: Баянзүрх дүүргийн 8-р хороо, Хилчдийн гудамжнаас 92-р сургуулийн хойд талаар Эрдэнэтолгой 52-р гудамж хүртэлх авто замын ажил | I7: Авто зам | J7: 2026 | K7: Нийслэл
A8: 4 | B8: II-87 | C8: 2026.01.29 А/119 | D8: 2 | E8: - | F8: 105977000 | H8: Баянгол, Баянзүрх, Хан-Уул, Сонгинохайрхан дүүргийн нутаг дэвсгэр Туул-1 коллектор ариутгах татуургын шугам сүлжээ ажил | I8: Инженерийн байгууламж | J8: 2026 | K8: Нийслэл
A9: 5 | B9: II-90 | C9: 2026.01.30 А/145 | D9: 1 | E9: 2396 | F9: 1932176291 | H9: Баянгол дүүргийн 20 дугаар хорооны нутаг дэвсгэрт баригдах “ТЭЦ-5 дулааны цахилгаан станцын барих ажил” | I9: Авто зам | J9: 2026 | K9: Нийслэл
A10: 6 | B10: II-98 | C10: 2026.02.02 А/162 | D10: 1 | F10: 603631 | H10: Чингэлтэй дүүрэг, 17-р хороо, Гэр хорооллын нийтийн тээврийн үйлчилгээг сайжруулах төсөл | I10: Авто зам | J10: 2026 | K10: Нийслэл
A11: 7 | B11: lll-1 | C11: A/135 2026.01.30 | D11: 4 | E11: 2797 | F11: 316805000 | H11: Хан-Уул дүүргийн 12 дугаар хорооны нутаг дэвсгэрт “Хог шатааж, эрчим хүч гаргах үйлдвэр” байгуулах ажил | I11: Хог хаягдал | J11: 2026 | K11: Нийслэл
A12: 8 | B12: lll-2 | C12: A/136 2026.01.30 | D12: 1 | E12: 293 | F12: 243453000 | H12: Хан-Уул дүүргийн 6 дугаар хорооны нутаг дэвсгэрт “Гал түймэр унтраах аврах анги шинээр барих” ажил | I12: Гамшгаас хамгаалах | J12: 2026 | K12: Нийслэл
A13: 9 | B13: С-01 | C13: 2026.02.03 A/175 | D13: 5 | E13: 2277 | F13: 621631500 | H13: Сүхбаатар дүүрэг, Чингэлтэй дүүрэг Сэлбэ дэд төв | I13: Дэд төв | J13: 2026 | K13: Нийслэл
A14: 10 | B14: II-1 | C14: 2026.02.12 А/221 | D14: 3 | E14: 1236 | F14: 843422000 | H14: Баянгол дүүрэг 9-р хороо Ерөнхий боловсролын 146-р сургууль орчимд хийгдэх явган зам, авто зам | I14: Авто зам | J14: 2026 | K14: Нийслэл
A15: 11 | B15: II-2 | C15: 2026.02.12 А/219 | D15: 2 | F15: 91935600 | H15: Баянгол, Баянзүрх, Сонгинохайрхан, Хан-Уул дүүргийн нутаг дэвсгэр Туулын хурдны зам барих ажил | I15: Авто зам | J15: 2026 | K15: Нийслэл
A16: 12 | B16: II-3 | C16: 2026.02.12 А/220 | D16: 1 | E16: 449 | F16: 147060000 | H16: Сүхбаатар дүүрэг 11, 12, 13 дугаар хороо Сэлбэ голын баруун эрэг дагуух 2.5 км авто зам | I16: Авто зам | J16: 2026 | K16: Нийслэл
A17: 13 | B17: lll-3 | C17: A/187 2026.02.05 | D17: 14 | E17: 6120 | F17: 3562269000 | H17: Сонгинохайрхан дүүргийн 23 дугаар хорооны нутаг дэвсгэрт баригдах “960 хүүхдийн суудал бүхий сургууль барих” ажил | I17: Сургууль | J17: 2026 | K17: Нийслэл
A18: 14 | B18: lll-4 | C18: A/223 2026.02.12 | D18: 7 | E18: 3347 | F18: 1804136000 | H18: Сонгинохайрхан дүүргийн 23 дугаар хорооны нутаг дэвсгэрт баригдах “960 хүүхдийн суудал бүхий сургууль барих” ажил | I18: Сургууль | J18: 2026 | K18: Нийслэл
A19: 15 | B19: II-5 | C19: 2026.02.16 А/252 | D19: 1 | E19: 3481 | F19: 1966733000 | H19: Баянгол дүүргийн 20 дугаар хорооны нутаг дэвсгэрт баригдах “ТЭЦ-5 дулааны цахилгаан станц барих ажил” | I19: Инженерийн байгууламж | J19: 2026 | K19: Нийслэл
A20: 16 | B20: 1 | C20: 2026.02.14 А/263 | D20: 12 | E20: 5459.09 | F20: 2530238000 | H20: Сонгинохайрхан дүүргийн 4 дүгээр хороо, Их Наран орчмын гэр хорооллын газрыг дахин төлөвлөх ажил | I20: Гэр хорооллын дахин төлөвлөлт | J20: 2026 | K20: Нийслэл
A21: 17 | B21: 2 | C21: 2026.02.14 А/264 | D21: 1 | E21: 349 | F21: 527795000 | H21: Ногоон нуур орчим Баянбүрд хэсэгчилсэн ерөнхий төлөвлөгөө | I21: Гэр хорооллын дахин төлөвлөлт | J21: 2026 | K21: ТХХТ, ХААН банк
A22: 18 | B22: С-02 | C22: 2026.02.28 А/284 | D22: 3 | E22: 2100 | F22: 74368200 | H22: Сүхбаатар дүүрэг, Чингэлтэй дүүрэг Сэлбэ дэд төв | I22: Дэд төв | J22: 2026 | K22: Нийслэл
A23: 19 | B23: 3 | C23: 2026.03.03 А/295 | D23: 5 | E23: 1849.14 | F23: 3958424800 | H23: Сүхбаатар дүүргийн 9 дүгээр хороо Баянбүрд орчмын хэсэгчилсэн ерөнхий төлөвлөгөөний хэрэгжилт Он дамжих санхүүжилт | I23: Гэр хорооллын дахин төлөвлөлт | J23: 2026 | K23: ТХХТ, ХААН банк
A24: 20 | B24: 4 | C24: 2026.03.03 А/294 | D24: 3 | E24: 1399 | F24: 415058600 | H24: Сүхбаатар дүүрэг 9 дүгээр хороо Спорт цогцолбор (Улаанбаатар Арена) Он дамжих санхүүжилт | I24: Гэр хорооллын дахин төлөвлөлт | J24: 2026 | K24: ТХХТ, Шунхлай
A25: 21 | B25: lll-5 | C25: A/265 2026.02.25 | D25: 5 | E25: 1735 | F25: 952790000 | H25: Сонгинохайрхан дүүргийн 23 дугаар хорооны нутаг дэвсгэрт баригдах “960 хүүхдийн суудал бүхий сургууль барих” ажил | I25: Сургууль | J25: 2026 | K25: Нийслэл
A26: 22 | B26: lll-6 | C26: A/293 2026.03.02 | D26: 3 | E26: 2097 | F26: 45180000 | H26: Хан-Уул дүүргийн 12 дугаар хорооны нутаг дэвсгэрт “Хог шатааж, эрчим хүч гаргах үйлдвэр” байгуулах ажил | I26: Хог хаягдал | J26: 2026 | K26: Нийслэл
A27: 23 | B27: II-8 | C27: 2026.03.09 А/321 | D27: 3 | E27: - | F27: 496177400 | H27: Баянгол, Баянзүрх, Хан-Уул, Сонгинохайрхан дүүргийн нутаг дэвсгэр Туул-1 коллектор ариутгах татуургын шугам сүлжээ ажил | I27: Инженерийн байгууламж | J27: 2026 | K27: Нийслэл
A28: 24 | B28: lll-7 | C28: A/350 2026.03.11 | D28: 3 | E28: 2100 | F28: 2694947000 | H28: Баянгол дүүргийн 16 дугаар хорооны нутаг дэвсгэрт баригдах “640 хүүхдийн суудалтай сургуулийн барилга”-ын ажил | I28: Сургууль | J28: 2026 | K28: Нийслэл
A29: 25 | B29: lll-8 | C29: A/362 2026.03.13 | D29: 9 | E29: 6095 | F29: 553660000 | H29: Хан-Уул дүүргийн 12 дугаар хорооны нутаг дэвсгэрт “Хог шатааж, эрчим хүч гаргах үйлдвэр” байгуулах ажил | I29: Хог хаягдал | J29: 2026 | K29: Нийслэл
A30: 26 | B30: lll-9 | C30: A/361 2026.03.13 | D30: 3 | E30: 1473.94 | F30: 430737000 | H30: Сонгинохайрхан дүүргийн 4 дүгээр хорооны нутаг дэвсгэрт баригдах “Сургуулийн өргөтгөлийн барилга байгууламж баригдах” ажил | I30: Сургууль | J30: 2026 | K30: Нийслэл
A31: 27 | B31: lll-10 | C31: A/395 2026.03.23 | D31: 1 | E31: 430 | F31: 1337911494 | H31: Хан-Уул дүүргийн 6 дугаар хорооны нутаг дэвсгэрт “Гал түймэр унтраах аврах анги шинээр барих” ажил | I31: Гамшгаас хамгаалах | J31: 2026 | K31: Нийслэл
A32: 28 | B32: lll-11 | C32: A/394 2026.03.23 | D32: 10 | E32: 4373 | F32: 2213013000 | H32: Хан-Уул дүүргийн 9 дүгээр хорооны нутаг дэвсгэрт баригдах “960 хүүхдийн суудалтай сургуулийн барилга”-ын ажил | I32: Сургууль | J32: 2026 | K32: Нийслэл
A33: 29 | B33: lll-12 | C33: A/393 2026.03.23 | D33: 1 | E33: 500 | F33: 49035000 | H33: Хан-Уул дүүргийн 12 дугаар хорооны нутаг дэвсгэрт “Хог шатааж, эрчим хүч гаргах үйлдвэр” байгуулах ажил | I33: Хог хаягдал | J33: 2026 | K33: Нийслэл
A34: 30 | B34: II-4 | C34: 2026.02.16 А/253 | D34: 1 | E34: 598 | F34: 242858000 | H34: Сонгинохайрхан дүүргийн 23 дугаар хорооны нутаг дэвсгэр Гэр хорооллын дахин төлөвлөлтийн Оргил төслийн инженерийн шугам сүлжээний ажил | I34: Инженерийн байгууламж | J34: 2026 | K34: Нийслэл
A35: 31 | B35: II-6 | C35: 2026.03.18 А/368 | D35: 4 | E35: 976.12 | G35: 319384000 | H35: Баянзүрх дүүргийн 10, 12, 37 дугаар хорооны нутаг дэвсгэрт Нарны замын зүүн өргөтгөл 4 км шинээр баригдах авто замын ажил | I35: Авто зам | J35: 2026 | K35: Олон улс
A36: 32 | B36: II-7 | C36: 2026.03.16 А/366 | D36: 1 | E36: 151 | F36: 36349000 | H36: Сонгинохайрхан дүүргийн 6, 23, 30, 31, 37, 43 дугаар хороо, Баянгол дүүргийн 21 дүгээр хорооны нутаг дэвсгэрт баригдаж буй “Толгойтын авто замыг Ард Аюушийн өргөн чөлөөтэй холбох авто замын гүүрэн байгууламж, олон түвшний огтлолцол” | I36: Авто зам | J36: 2026 | K36: Нийслэл
A37: 33 | B37: II-10 | C37: 2026.03.26 А/422 | D37: 1 | E37: 1080 | F37: 1019414000 | H37: Баянгол дүүргийн 20 дугаар хорооны нутаг дэвсгэрт баригдах “ТЭЦ-5 дулааны цахилгаан станц барих ажил” | I37: Инженерийн байгууламж | J37: 2026 | K37: Нийслэл
A38: 34 | B38: II-12 | C38: 2026.03.26 А/425 | D38: 1 | E38: 47 | F38: 20606000 | H38: Баянгол дүүргийн 11, 22, 23, 34 дүгээр хороо, Энхбаярын зам орчимд хийгдэх явган зам, авто замын ажил | I38: Авто зам | J38: 2026 | K38: Нийслэл
A39: 35 | B39: II-13 | C39: 2026.03.26 А/421 | D39: 3 | E39: 5212 | F39: 1869550000 | H39: Баянгол дүүргийн 20 дугаар хорооны нутаг дэвсгэрт баригдах “ТЭЦ-5 дулааны цахилгаан станц барих ажил” | I39: Инженерийн байгууламж | J39: 2026 | K39: Нийслэл
A40: 36 | B40: II-15 | C40: 2026.03.26 А/424 | D40: 1 | E40: 597 | F40: 310285000 | H40: Сонгинохайрхан дүүргийн 23 дугаар хорооны нутаг дэвсгэр Гэр хорооллын дахин төлөвлөлтийн Оргил төслийн инженерийн шугам сүлжээний ажил | I40: Инженерийн байгууламж | J40: 2026 | K40: Нийслэл
...

Sheet Өнгөт хүснэгт
B2: Үзүүлэлт | C2: Хэмжих нэгж | D2: Нийслэлийн төсвийн газар чөлөөлөлт, нөхөх олговор | E2: Улаанбаатар хотын Тогтвортой авто зам, тээвэр төсөл | F2: Нийт
B3: Батлагдсан төсөв | C3: тэрбум төгрөг | D3: 322.582 | E3: 19 | F3: =+D3+E3 -> 341.582
B4: Захирамж гарсан | C4: Нэгж талбарын тоо | D4: =F4-E4 -> 733 | E4: ='7р хавсралт_322.58тэрбум'!D35+'7р хавсралт_322.58тэрбум'!D62+'7р хавсралт_322.58тэрбум'!D114+'7р хавсралт_322.58тэрбум'!D151 -> 17 | F4: ='7р хавсралт_322.58тэрбум'!D177 -> 750
C5: Хэмжээ, га | D5: =F5-E5 -> 60.160017 | E5: =('7р хавсралт_322.58тэрбум'!E35+'7р хавсралт_322.58тэрбум'!E62+'7р хавсралт_322.58тэрбум'!E114+'7р хавсралт_322.58тэрбум'!E151)/10000 -> 0.733312 | F5: ='7р хавсралт_322.58тэрбум'!E177/10000 -> 60.893329
C6: Тэрбум төгрөг | D6: =F6-E6 -> 220.80154 | E6: =('7р хавсралт_322.58тэрбум'!G35+'7р хавсралт_322.58тэрбум'!G62+'7р хавсралт_322.58тэрбум'!G114+'7р хавсралт_322.58тэрбум'!G151)/1000000000 -> 3.800528 | F6: ='7р хавсралт_322.58тэрбум'!H229/1000000000 -> 224.60207
B7: Захирамжийн төсөлд хянагдаж байгаа | C7: Нэгж талбарын тоо | D7: =F7-E7 -> 297 | E7: ='7р хавсралт_322.58тэрбум'!D190 -> 2 | F7: ='7р хавсралт_322.58тэрбум'!D225 -> 299
C8: Хэмжээ, га | D8: =F8-E8 -> 15.30908 | E8: =('7р хавсралт_322.58тэрбум'!E190)/10000 -> 0.0937 | F8: ='7р хавсралт_322.58тэрбум'!E225/10000 -> 15.40278
C9: Тэрбум төгрөг | D9: =F9-E9 -> 100.99711 | E9: =('7р хавсралт_322.58тэрбум'!G190)/1000000000 -> 0.508545 | F9: ='7р хавсралт_322.58тэрбум'!H230/1000000000 -> 101.50566
B10: БҮГД | C10: Нэгж талбарын тоо | D10: =F10-E10 -> 1030 | E10: =E4+E7 -> 19 | F10: =F4+F7 -> 1049
C11: Хэмжээ, га | D11: =F11-E11 -> 75.469097 | E11: =E5+E8 -> 0.827012 | F11: =F5+F8 -> 76.296109
C12: Тэрбум төгрөг | D12: =F12-E12 -> 321.79865 | E12: =E6+E9 -> 4.309073 | F12: =F6+F9 -> 326.10773
B13: Бодит үлдэгдэл | C13: Тэрбум төгрөг | D13: ='7р хавсралт_322.58тэрбум'!F232/1000000000 -> 0.78354782 | E13: ='7р хавсралт_322.58тэрбум'!G232/1000000000 -> 14.692454 | F13: ='7р хавсралт_322.58тэрбум'!H232/1000000000 -> 15.476002
C15: үлдэгдэл хувь | D15: =D13/D3*100 -> 0.2428988 | E15: =E13/E3*100 -> 77.328705
C16: зарцуулсан хувь | D16: =100-D15 -> 99.757101 | E16: =100-E15 -> 22.671295
D17: =D6+D9 -> 321.79865
